Workbook

Sheet Master Task Tracker
A1: TASK MONITORING REPORT STI College Puerto Princesa
A2: Entry Date | B2: Name | C2: Position | D2: Department | E2: Task Category | F2: Specific Task | G2: Target Date | H2: Priority | I2: Status | J2: % Progress | K2: Remarks | M2: Evidence/Link
A3: 46128 | B3: Nimrod Palatino | C3: School Registrar | D3: Admin | E3: CHED | F3: LBP ATM Orientation | G3: 46128 | H3: High | I3: Completed | J3: =IF(I3="Completed",100,IF(I3="Ongoing",50,IF(I3="For Review",75,IF(I3="Delayed",30,0)))) -> 100
A4: 46128 | B4: Nimrod Palatino | C4: School Registrar | D4: Admin | E4: HQ | F4: 2T 25-26 NS Sail | G4: 46129 | H4: High | I4: Completed | J4: =IF(I4="Completed",100,IF(I4="Ongoing",50,IF(I4="For Review",75,IF(I4="Delayed",30,0)))) -> 100
A5: 46129 | B5: Julius Cosio | C5: MIS | D5: Admin | E5: HQ | F5: TAM System | G5: 17/30/2026 | H5: High | I5: Completed | J5: =IF(I5="Completed",100,IF(I5="Ongoing",50,IF(I5="For Review",75,IF(I5="Delayed",30,0)))) -> 100
A6: 46129 | B6: Joaquin Villanueva | C6: MIS | D6: Admin | E6: HQ | F6: TAM System | G6: 17/30/2026 | H6: High | I6: Completed | J6: =IF(I6="Completed",100,IF(I6="Ongoing",50,IF(I6="For Review",75,IF(I6="Delayed",30,0)))) -> 100
A7: 46129 | B7: Jane Cristine Ganancial | C7: Alumni & Placement Officer | D7: Admin | E7: HQ | F7: DBP 2024-25 Graduate Tracer | G7: 46129 | H7: High | I7: Completed | J7: =IF(I7="Completed",100,IF(I7="Ongoing",50,IF(I7="For Review",75,IF(I7="Delayed",30,0)))) -> 100
A8: 46177 | B8: Jane Cristine Ganancial | C8: Alumni & Placement Officer | D8: Admin | E8: NCF | F8: Conduct of NCF | G8: 46177 | H8: High | I8: Completed | J8: =IF(I8="Completed",100,IF(I8="Ongoing",50,IF(I8="For Review",75,IF(I8="Delayed",30,0)))) -> 100
A9: 46147 | B9: Jane Cristine Ganancial | C9: Alumni & Placement Officer | D9: Admin | E9: HO | F9: Alumni Database - Jan to Mar '26 | G9: 46149 | H9: High | I9: Completed | J9: =IF(I9="Completed",100,IF(I9="Ongoing",50,IF(I9="For Review",75,IF(I9="Delayed",30,0)))) -> 100
A10: 46147 | B10: Jane Cristine Ganancial | C10: Alumni & Placement Officer | D10: Admin | E10: HO | F10: School Job Postings – April 2026 | G10: 46150 | H10: High | I10: Completed | J10: =IF(I10="Completed",100,IF(I10="Ongoing",50,IF(I10="For Review",75,IF(I10="Delayed",30,0)))) -> 100
A11: 46147 | B11: Jane Cristine Ganancial | C11: Alumni & Placement Officer | D11: Admin | E11: HO | F11: School Masterlist of Partners SY2526 | G11: 46156 | H11: High | I11: Completed | J11: =IF(I11="Completed",100,IF(I11="Ongoing",50,IF(I11="For Review",75,IF(I11="Delayed",30,0)))) -> 100
A12: 46147 | B12: Jane Cristine Ganancial | C12: Alumni & Placement Officer | D12: Admin | E12: HO | F12: Survey to Alumni for 3rd Quarter | G12: 46148 | H12: High | I12: Completed | J12: =IF(I12="Completed",100,IF(I12="Ongoing",50,IF(I12="For Review",75,IF(I12="Delayed",30,0)))) -> 100
A13: 46147 | B13: Jane Cristine Ganancial | C13: Alumni & Placement Officer | D13: Admin | E13: NCF | F13: Follow up invites for NCF | G13: 46173 | H13: High | I13: Completed | J13: =IF(I13="Completed",100,IF(I13="Ongoing",50,IF(I13="For Review",75,IF(I13="Delayed",30,0)))) -> 100
A14: 46129 | B14: Ronalyn Saldavia | C14: Cashier | D14: Admin | E14: Deposit | F14: Cash counting & Deposit | G14: 46129 | H14: High | I14: Completed | J14: =IF(I14="Completed",100,IF(I14="Ongoing",50,IF(I14="For Review",75,IF(I14="Delayed",30,0)))) -> 100
A15: 46141 | B15: Mary Ellen Venice Cruz | C15: Guidance Counselor | D15: Admin | E15: Information Service | F15: Mental Health Activity and Seminar with AKAPP - City Youth Development Office | G15: 46141 | H15: High | I15: Completed | J15: =IF(I15="Completed",100,IF(I15="Ongoing",50,IF(I15="For Review",75,IF(I15="Delayed",30,0)))) -> 100
A16: 46142 | B16: Mary Ellen Venice Cruz | C16: Guidance Counselor | D16: Admin | E16: Career Guidance | F16: Career Planning Survey for Grade 11 | G16: 46150 | H16: High | I16: Completed | J16: =IF(I16="Completed",100,IF(I16="Ongoing",50,IF(I16="For Review",75,IF(I16="Delayed",30,0)))) -> 100 | K16: Deadline for the consolidation of data and submission to HO is on May 8, 2026. | M16: Sent thru email.
A17: 46146 | B17: Mary Ellen Venice Cruz | C17: Guidance Counselor | D17: Admin | E17: Career Guidance | F17: Administration of MCPOA for HUMSS 11 students | G17: 46146 | H17: High | I17: Ongoing | J17: =IF(I17="Completed",100,IF(I17="Ongoing",50,IF(I17="For Review",75,IF(I17="Delayed",30,0)))) -> 50
A18: 46146 | B18: Mary Ellen Venice Cruz | C18: Guidance Counselor | D18: Admin | E18: Student Assisstanship | F18: Pending RFA Approval of SA salary (Covered period: March-April 2026) | G18: 46147 | H18: High | I18: Completed | J18: =IF(I18="Completed",100,IF(I18="Ongoing",50,IF(I18="For Review",75,IF(I18="Delayed",30,0)))) -> 100 | K18: Approved by HO as of 5/7.
A19: 46146 | B19: Mary Ellen Venice Cruz | C19: Guidance Counselor | D19: Admin | E19: Alumni and Placement Services | F19: Creation and endorsement of STI Job+ account to APO | G19: 46147 | H19: Medium | I19: Completed | J19: =IF(I19="Completed",100,IF(I19="Ongoing",50,IF(I19="For Review",75,IF(I19="Delayed",30,0)))) -> 100 | K19: Endorsed to Ms. Jane.
A20: 46146 | B20: Mary Ellen Venice Cruz | C20: Guidance Counselor | D20: Admin | E20: Recruitment Process | F20: Conduct initial interview and administer pre-employment screening tests. | G20: 46146 | H20: Medium | I20: Completed | J20: =IF(I20="Completed",100,IF(I20="Ongoing",50,IF(I20="For Review",75,IF(I20="Delayed",30,0)))) -> 100 | K20: Endorsed to Ms. Lamban
A21: 46147 | B21: Mary Ellen Venice Cruz | C21: Guidance Counselor | D21: Admin | E21: Information Service | F21: Updating of GCO Daily Log | G21: 46147 | H21: Medium | I21: Completed | J21: =IF(I21="Completed",100,IF(I21="Ongoing",50,IF(I21="For Review",75,IF(I21="Delayed",30,0)))) -> 100
A22: 46150 | B22: Mary Ellen Venice Cruz | C22: Guidance Counselor | D22: Admin | E22: APS & SDW Career Readiness Webinar Series | F22: Disseminate MS forms registration link to 1y-2y and 4y tertiary students. | G22: 5/19-20/2026 | H22: Medium | I22: Completed | J22: =IF(I22="Completed",100,IF(I22="Ongoing",50,IF(I22="For Review",75,IF(I22="Delayed",30,0)))) -> 100 | K22: Coordinated to Ms. Jane. Pubmats will be posted on STI official FB page. | M22: https://stiedu-my.sharepoint.com/:b:/g/personal/ellen_cruz_puertoprincesa_sti_edu/IQAiT-uxuJq2SIOR9e0MFqSkAYfZ1GrHgTuOAR_Z1fwhYT4?e=arpNLY
A23: 46156 | B23: Mary Ellen Venice Cruz | C23: Guidance Counselor | D23: Admin | E23: Records | F23: Compilation of Certificate of Completion of Batch 24-25 | G23: 46156 | H23: Medium | I23: Completed | J23: =IF(I23="Completed",100,IF(I23="Ongoing",50,IF(I23="For Review",75,IF(I23="Delayed",30,0)))) -> 100
A24: 46160 | B24: Mary Ellen Venice Cruz | C24: Guidance Counselor | D24: Admin | E24: Professional Consultation | F24: Validation of research questionnaires for Grade 11 students | G24: 46160 | H24: Medium | I24: Completed | J24: =IF(I24="Completed",100,IF(I24="Ongoing",50,IF(I24="For Review",75,IF(I24="Delayed",30,0)))) -> 100
A25: 46161 | B25: Mary Ellen Venice Cruz | C25: Guidance Counselor | D25: Admin | E25: Information Service | F25: Updating of GCO Daily Log | G25: 46162 | H25: Medium | I25: Ongoing | J25: =IF(I25="Completed",100,IF(I25="Ongoing",50,IF(I25="For Review",75,IF(I25="Delayed",30,0)))) -> 50 | K25: The database is under maintenance.
A26: 46161 | B26: Mary Ellen Venice Cruz | C26: Guidance Counselor | D26: Admin | E26: Information Service | F26: Sumakses sa Careera Webinar | G26: 46161 | H26: Medium | I26: Completed | J26: =IF(I26="Completed",100,IF(I26="Ongoing",50,IF(I26="For Review",75,IF(I26="Delayed",30,0)))) -> 100 | K26: Intended for tertiary graduating students.
A27: 46162 | B27: Mary Ellen Venice Cruz | C27: Guidance Counselor | D27: Admin | E27: Internal Training | F27: Student and Stakeholder Services Training Facilitation | G27: 46183 | H27: Medium | I27: Ongoing | J27: =IF(I27="Completed",100,IF(I27="Ongoing",50,IF(I27="For Review",75,IF(I27="Delayed",30,0)))) -> 50 | K27: Training workshop preparation is ongoing. | M27: https://canva.link/usl9l5589dvzwhf
A28: 46163 | B28: Mary Ellen Venice Cruz | C28: Guidance Counselor | D28: Admin | E28: Student Concerns | F28: Addressing student concerns | G28: 46163 | H28: High | I28: Completed | J28: =IF(I28="Completed",100,IF(I28="Ongoing",50,IF(I28="For Review",75,IF(I28="Delayed",30,0)))) -> 100
A29: 46164 | B29: Mary Ellen Venice Cruz | C29: Guidance Counselor | D29: Admin | E29: Professional Consultation | F29: Research paneling for BSTM 2 | I29: Completed | J29: =IF(I29="Completed",100,IF(I29="Ongoing",50,IF(I29="For Review",75,IF(I29="Delayed",30,0)))) -> 100
A30: 46165 | B30: Mary Ellen Venice Cruz | C30: Guidance Counselor | D30: Admin | E30: Marketing | F30: Follow up online and walk-in registrants thru phone patch. | G30: 46165 | I30: Completed | J30: =IF(I30="Completed",100,IF(I30="Ongoing",50,IF(I30="For Review",75,IF(I30="Delayed",30,0)))) -> 100
A31: 46167 | B31: Mary Ellen Venice Cruz | C31: Guidance Counselor | D31: Admin | E31: Issuance of Good Moral Certificate | G31: 46168 | H31: Medium | I31: Completed | J31: =IF(I31="Completed",100,IF(I31="Ongoing",50,IF(I31="For Review",75,IF(I31="Delayed",30,0)))) -> 100
A32: 46167 | B32: Mary Ellen Venice Cruz | C32: Guidance Counselor | D32: Admin | E32: Information Service | F32: Updating of GCO Daily Log | G32: 46167 | H32: Medium | I32: Ongoing | J32: =IF(I32="Completed",100,IF(I32="Ongoing",50,IF(I32="For Review",75,IF(I32="Delayed",30,0)))) -> 50
A33: 46168 | B33: Mary Ellen Venice Cruz | C33: Guidance Counselor | D33: Admin | E33: Organizing Calendar of Activities | F33: Plotting the approved activities on the calendar planner | J33: =IF(I33="Completed",100,IF(I33="Ongoing",50,IF(I33="For Review",75,IF(I33="Delayed",30,0)))) -> 0
A34: 46168 | B34: Mary Ellen Venice Cruz | C34: Guidance Counselor | D34: Admin | E34: Issuance of Good Moral Certificate | G34: 46168 | H34: Medium | I34: Completed | J34: =IF(I34="Completed",100,IF(I34="Ongoing",50,IF(I34="For Review",75,IF(I34="Delayed",30,0)))) -> 100
A35: 46170 | B35: Mary Ellen Venice Cruz | C35: Guidance Counselor | D35: Admin | E35: Student Assisstanship | F35: Processing of SA salary (Covered period: April-May 2026) | G35: 46170 | H35: Medium | I35: Completed | J35: =IF(I35="Completed",100,IF(I35="Ongoing",50,IF(I35="For Review",75,IF(I35="Delayed",30,0)))) -> 100
A36: 46170 | B36: Mary Ellen Venice Cruz | C36: Guidance Counselor | D36: Admin | E36: Student Concerns | F36: Follow-up student concerns | G36: 46171 | H36: High | I36: Completed | J36: =IF(I36="Completed",100,IF(I36="Ongoing",50,IF(I36="For Review",75,IF(I36="Delayed",30,0)))) -> 100
A37: 46171 | B37: Mary Ellen Venice Cruz | C37: Guidance Counselor | D37: Admin | E37: Professional Consultation | F37: Validating research questionnaires of G11 students | G37: 46171 | H37: Medium | I37: Completed | J37: =IF(I37="Completed",100,IF(I37="Ongoing",50,IF(I37="For Review",75,IF(I37="Delayed",30,0)))) -> 100
A38: 46171 | B38: Mary Ellen Venice Cruz | C38: Guidance Counselor | D38: Admin | E38: Student Assisstanship | F38: Processing of SA salary (Covered period: April-May 2026) | G38: 46171 | H38: High | I38: Completed | J38: =IF(I38="Completed",100,IF(I38="Ongoing",50,IF(I38="For Review",75,IF(I38="Delayed",30,0)))) -> 100
A39: 46174 | B39: Mary Ellen Venice Cruz | C39: Guidance Counselor | D39: Admin | E39: Career Guidance | F39: Administration of MCPOA for STEM 11 students | G39: 46174 | H39: High | I39: Completed | J39: =IF(I39="Completed",100,IF(I39="Ongoing",50,IF(I39="For Review",75,IF(I39="Delayed",30,0)))) -> 100
A40: 46174 | B40: Mary Ellen Venice Cruz | C40: Guidance Counselor | D40: Admin | E40: Career Guidance | F40: Career Planning Activity in Brgy Bagong Sikap | G40: 46174 | H40: High | I40: Completed | J40: =IF(I40="Completed",100,IF(I40="Ongoing",50,IF(I40="For Review",75,IF(I40="Delayed",30,0)))) -> 100
...

Sheet Monthly Summary
A1: Total Tasks | B1: =COUNTA('Master Task Tracker'!B3:B268) -> 266 | D1: Status
A2: Completed Tasks | B2: =COUNTIF('Master Task Tracker'!I3:I268,"Completed") -> 246 | D2: Completed | E2: =COUNTIF('Master Task Tracker'!I3:I268,"Completed") -> 246
A3: Delayed Tasks | B3: =COUNTIF('Master Task Tracker'!I3:I268,"Delayed") -> 0 | D3: Ongoing | E3: =COUNTIF('Master Task Tracker'!I3:I268,"Ongoing") -> 8
A4: Completion Rate | B4: =IF(B1=0,0,B2/B1) -> 0.92481203 | D4: Delayed | E4: =COUNTIF('Master Task Tracker'!I3:I268,"Delayed") -> 0

Sheet Individual Performance
A1: Staff Name | B1: Total Tasks | C1: Completed | D1: Delayed | E1: Completion %
